<?xml version="1.0" encoding="utf-8"?>

<robot
  name="robot_platform">

  <link name="dummy"></link>

  <link name="link_0">
    <inertial>
      <origin
        xyz="0.123669470890958 -1.55431223447522E-15 0.0157873116993668"
        rpy="0 0 0" />
      <mass
        value="6.52316744505344" />
      <inertia
        ixx="0.0385919077427861"
        ixy="-1.42698858839734E-16"
        ixz="-8.43576589332318E-05"
        iyy="0.0585218852507233"
        iyz="8.03899668248163E-17"
        izz="0.0423119666555374" />
    </inertial>
    <visual>
      <origin
        xyz="0 0 0"
        rpy="0 0 0" />
      <geometry>
        <mesh
          filename="package://fyp_sim/meshes/link_0.STL" />
      </geometry>
      <material
        name="">
        <color
          rgba="0.752941176470588 0.752941176470588 0.752941176470588 1" />
      </material>
    </visual>
    <collision>
      <origin
        xyz="0 0 0"
        rpy="0 0 0" />
      <geometry>
        <mesh
          filename="package://fyp_sim/meshes/link_0.STL" />
      </geometry>
    </collision>
  </link>

  <link name="link_1">
    <inertial>
      <origin
        xyz="-2.4980018054066E-16 1.11022302462516E-16 -0.140248446514204"
        rpy="0 0 0" />
      <mass
        value="0.853825179360506" />
      <inertia
        ixx="0.00259189846991135"
        ixy="2.99550060933435E-17"
        ixz="2.12803718614051E-20"
        iyy="0.00473869680320454"
        iyz="-7.59085432106584E-18"
        izz="0.00237094198835257" />
    </inertial>
    <visual>
      <origin
        xyz="0 0 0"
        rpy="0 0 0" />
      <geometry>
        <mesh
          filename="package://fyp_sim/meshes/link_1.STL" />
      </geometry>
      <material
        name="">
        <color
          rgba="0.752941176470588 0.752941176470588 0.752941176470588 1" />
      </material>
    </visual>
    <collision>
      <origin
        xyz="0 0 0"
        rpy="0 0 0" />
      <geometry>
        <mesh
          filename="package://fyp_sim/meshes/link_1.STL" />
      </geometry>
    </collision>
  </link>

  <!-- <link name="link_2">
    <inertial>
      <origin
        xyz="-2.4980018054066E-16 1.0842021724855E-16 -0.140248446514204"
        rpy="0 0 0" />
      <mass
        value="0.853825179360506" />
      <inertia
        ixx="0.00259189846991135"
        ixy="2.26390736758926E-17"
        ixz="-1.65864202178245E-20"
        iyy="0.00473869680320454"
        iyz="-7.56161929147912E-18"
        izz="0.00237094198835257" />
    </inertial>
    <visual>
      <origin
        xyz="0 0 0"
        rpy="0 0 0" />
      <geometry>
        <mesh
          filename="package://fyp_sim/meshes/link_2.STL" />
      </geometry>
      <material
        name="">
        <color
          rgba="0.752941176470588 0.752941176470588 0.752941176470588 1" />
      </material>
    </visual>
    <collision>
      <origin
        xyz="0 0 0"
        rpy="0 0 0" />
      <geometry>
        <mesh
          filename="package://fyp_sim/meshes/link_2.STL" />
      </geometry>
    </collision>
  </link>

  <link name="link_3">
    <inertial>
      <origin
        xyz="5.55111512312578E-17 4.44089209850063E-16 0.0314757907344973"
        rpy="0 0 0" />
      <mass
        value="3.7018874029961" />
      <inertia
        ixx="0.0278776150094656"
        ixy="1.12661999429725E-18"
        ixz="-1.10321899209888E-18"
        iyy="0.0278776150094656"
        iyz="3.56099902819009E-16"
        izz="0.0534059176580867" />
    </inertial>
    <visual>
      <origin
        xyz="0 0 0"
        rpy="0 0 0" />
      <geometry>
        <mesh
          filename="package://fyp_sim/meshes/link_3.STL" />
      </geometry>
      <material
        name="">
        <color
          rgba="0.792156862745098 0.819607843137255 0.933333333333333 1" />
      </material>
    </visual>
    <collision>
      <origin
        xyz="0 0 0"
        rpy="0 0 0" />
      <geometry>
        <mesh
          filename="package://fyp_sim/meshes/link_3.STL" />
      </geometry>
    </collision>
  </link>

  <link name="link_4">
    <inertial>
      <origin
        xyz="-2.77555756156289E-17 4.44089209850063E-16 0.0324909844927062"
        rpy="0 0 0" />
      <mass
        value="3.7018874029961" />
      <inertia
        ixx="0.0278776150094656"
        ixy="-1.13323743919842E-18"
        ixz="-5.14087984682169E-17"
        iyy="0.0278776150094656"
        iyz="3.56332401805764E-16"
        izz="0.0534059176580867" />
    </inertial>
    <visual>
      <origin
        xyz="0 0 0"
        rpy="0 0 0" />
      <geometry>
        <mesh
          filename="package://fyp_sim/meshes/link_4.STL" />
      </geometry>
      <material
        name="">
        <color
          rgba="0.792156862745098 0.819607843137255 0.933333333333333 1" />
      </material>
    </visual>
    <collision>
      <origin
        xyz="0 0 0"
        rpy="0 0 0" />
      <geometry>
        <mesh
          filename="package://fyp_sim/meshes/link_4.STL" />
      </geometry>
    </collision>
  </link> -->

  <joint name="dummy_joint" type="fixed">
    <parent
      link="dummy" />
    <child
      link="link_0" />
  </joint>

  <joint name="joint_1"
    type="continuous">
    <origin
      xyz="0.5175 -0.22 -0.02"
      rpy="0 0 0" />
    <parent
      link="link_0" />
    <child
      link="link_1" />
    <axis
      xyz="0 0 1" />
  </joint>

  <!-- <joint name="joint_2"
    type="continuous">
    <origin
      xyz="0.5175 0.22 -0.02"
      rpy="0 0 0" />
    <parent
      link="link_0" />
    <child
      link="link_2" />
    <axis
      xyz="0 0 1" />
  </joint>

  <joint name="joint_3"
    type="continuous">
    <origin
      xyz="-0.0725 0.22203 -0.11"
      rpy="1.5708 -1.5708 0" />
    <parent
      link="link_0" />
    <child
      link="link_3" />
    <axis
      xyz="0 0 1" />
  </joint>

  <joint name="joint_4"
    type="continuous">
    <origin
      xyz="-0.0725 -0.24 -0.11"
      rpy="1.5708 -1.5708 0" />
    <parent
      link="link_0" />
    <child
      link="link_4" />
    <axis
      xyz="0 0 -1" /> -->
</robot>
