<?xml version="1.0" encoding="utf-8"?>

<robot name="robot_platform_urdf" xmlns:xacro="http://www.ros.org/wiki/xacro">

  <!-- <xacro:include filename="$(find fyp_sim)/urdf/materials.xacro"/> -->
  <xacro:include filename="$(find fyp_sim)/urdf/robot.gazebo.xacro"/>


  <!-- dummy link -->
  <link name="base_footprint"/>

  <!-- chassis -->
  <link name="chassis">
    <inertial>
      <origin
        xyz="0 0 0"
        rpy="0 0 0" />
      <mass
        value="6.52316744505344" />
      <inertia
        ixx="0.0385919077427861"
        ixy="-1.42698858839734E-16"
        ixz="-8.43576589332318E-05"
        iyy="0.0585218852507233"
        iyz="8.03899668248163E-17"
        izz="0.0423119666555374" />
    </inertial>
    <visual>
      <origin
        xyz="0 0 0"
        rpy="0 0 0" />
      <geometry>
        <mesh
          filename="package://fyp_sim/meshes/chassis.stl" scale="0.01 0.01 0.01" />
      </geometry>
      <material
        name="chassis_material">
        <color
          rgba="0.5 0.5 0.5 1.0" />
      </material>
    </visual>
    <collision name="chassis_collision">>
      <origin
        xyz="0 0 0"
        rpy="0 0 ${-pi/2}" />
      <geometry>
        <mesh
          filename="package://fyp_sim/meshes/chassis.stl" scale="0.01 0.01 0.01" />
      </geometry>
    </collision>
  </link>

  <!-- back wheel left -->
  <link name="back_wheel_left">
    <inertial>
      <origin
        xyz="0 0 0"
        rpy="0 0 0" />
      <mass
        value="0.853825179360506" />
      <inertia
        ixx="0.00259189846991135"
        ixy="2.99550060933435E-17"
        ixz="2.12803718614051E-20"
        iyy="0.00473869680320454"
        iyz="-7.59085432106584E-18"
        izz="0.00237094198835257" />
    </inertial>
    <visual>
      <origin
        xyz="0 0 0"
        rpy="0 0 0" />
      <geometry>
        <mesh
          filename="package://fyp_sim/meshes/back_wheel.stl" scale="0.01 0.01 0.01"/>
      </geometry>
      <material
        name="back_wheel_left_material">
        <color
          rgba="0.0 0.0 0.0 1.0" />
      </material>
    </visual>
    <collision name="back_wheel_left_collision">
      <origin
        xyz="0 0 0"
        rpy="0 0 0" />
      <geometry>
        <mesh
          filename="package://fyp_sim/meshes/back_wheel.stl" scale="0.01 0.01 0.01"/>
      </geometry>
      <surface>
        <friction>
          <ode>
            <mu>0.8</mu>
            <mu2>0.8</mu2>
            <slip1>1.0</slip1>
            <slip2>1.0</slip2>
          </ode>
        </friction>
      </surface>
    </collision>
  </link>

  <!-- back wheel right -->
  <link name="back_wheel_right">
    <inertial>
      <origin
        xyz="0 0 0"
        rpy="0 0 0" />
      <mass
        value="0.853825179360506" />
      <inertia
        ixx="0.00259189846991135"
        ixy="2.99550060933435E-17"
        ixz="2.12803718614051E-20"
        iyy="0.00473869680320454"
        iyz="-7.59085432106584E-18"
        izz="0.00237094198835257" />
    </inertial>
    <visual>
      <origin
        xyz="0 0 0"
        rpy="0 0 0" />
      <geometry>
        <mesh
          filename="package://fyp_sim/meshes/back_wheel.stl" scale="0.01 0.01 0.01"/>
      </geometry>
      <material
        name="back_wheel_right_material">
        <color
          rgba="0.0 0.0 0.0 1.0" />
      </material>
    </visual>
    <collision name="back_wheel_right_collision">
      <origin
        xyz="0 0 0"
        rpy="0 0 0" />
      <geometry>
        <mesh
          filename="package://fyp_sim/meshes/back_wheel.stl" scale="0.01 0.01 0.01"/>
      </geometry>
      <surface>
        <friction>
          <ode>
            <mu>0.8</mu>
            <mu2>0.8</mu2>
            <slip1>1.0</slip1>
            <slip2>1.0</slip2>
          </ode>
        </friction>
      </surface>
    </collision>
  </link>

  <!-- front wheel left connector -->
  <link name="front_wheel_left_connector">
    <inertial>
      <origin
        xyz="0 0 0"
        rpy="0 0 0" />
      <mass
        value="0.853825179360506" />
      <inertia
        ixx="0.00259189846991135"
        ixy="2.99550060933435E-17"
        ixz="2.12803718614051E-20"
        iyy="0.00473869680320454"
        iyz="-7.59085432106584E-18"
        izz="0.00237094198835257" />
    </inertial>
    <visual>
      <origin
        xyz="0 0 0"
        rpy="0 0 0" />
      <geometry>
        <mesh
          filename="package://fyp_sim/meshes/front_wheel_connector.stl" scale="0.01 0.01 0.01"/>
      </geometry>
      <material
        name="front_wheel_left_connector_material">
        <color
          rgba="0.203125 0.238281 0.285156 1.0" />
      </material>
    </visual>
    <collision name="front_wheel_left_connector_collision">
      <origin
        xyz="0 0 0"
        rpy="0 0 0" />
      <geometry>
        <mesh
          filename="package://fyp_sim/meshes/front_wheel_connector.stl" scale="0.01 0.01 0.01"/>
      </geometry>
    </collision>
  </link>

  <!-- front wheel right connector -->
  <link name="front_wheel_right_connector">
    <inertial>
      <origin
        xyz="0 0 0"
        rpy="0 0 0" />
      <mass
        value="0.853825179360506" />
      <inertia
        ixx="0.00259189846991135"
        ixy="2.99550060933435E-17"
        ixz="2.12803718614051E-20"
        iyy="0.00473869680320454"
        iyz="-7.59085432106584E-18"
        izz="0.00237094198835257" />
    </inertial>
    <visual>
      <origin
        xyz="0 0 0"
        rpy="0 0 0" />
      <geometry>
        <mesh
          filename="package://fyp_sim/meshes/front_wheel_connector.stl" scale="0.01 0.01 0.01"/>
      </geometry>
      <material
        name="front_wheel_right_connector_material">
        <color
          rgba="0.203125 0.238281 0.285156 1.0" />
      </material>
    </visual>
    <collision name="front_wheel_right_connector_collision">
      <origin
        xyz="0 0 0"
        rpy="0 0 0" />
      <geometry>
        <mesh
          filename="package://fyp_sim/meshes/front_wheel_connector.stl" scale="0.01 0.01 0.01"/>
      </geometry>
    </collision>
  </link>

  <!-- front wheel right -->
  <link name="front_wheel_right">
    <inertial>
      <origin
        xyz="0 0 0"
        rpy="0 0 0" />
      <mass
        value="0.853825179360506" />
      <inertia
        ixx="0.00259189846991135"
        ixy="2.99550060933435E-17"
        ixz="2.12803718614051E-20"
        iyy="0.00473869680320454"
        iyz="-7.59085432106584E-18"
        izz="0.00237094198835257" />
    </inertial>
    <visual>
      <origin
        xyz="0 0 0"
        rpy="0 0 0" />
      <geometry>
        <mesh
          filename="package://fyp_sim/meshes/front_wheel.stl" scale="0.01 0.01 0.01"/>
      </geometry>
      <material
        name="front_wheel_right_material">
        <color
          rgba="0.0 0.0 0.0 1.0" />
      </material>
    </visual>
    <collision name="front_wheel_right_collision">
      <origin
        xyz="0 0 0"
        rpy="0 0 0" />
      <geometry>
        <mesh
          filename="package://fyp_sim/meshes/front_wheel.stl" scale="0.01 0.01 0.01"/>
      </geometry>
      <surface>
        <friction>
          <ode>
            <mu>0.8</mu>
            <mu2>0.8</mu2>
            <slip1>1.0</slip1>
            <slip2>1.0</slip2>
          </ode>
        </friction>
      </surface>
    </collision>
  </link>

  <!-- front wheel left -->
  <link name="front_wheel_left">
    <inertial>
      <origin
        xyz="0 0 0"
        rpy="0 0 0" />
      <mass
        value="0.853825179360506" />
      <inertia
        ixx="0.00259189846991135"
        ixy="2.99550060933435E-17"
        ixz="2.12803718614051E-20"
        iyy="0.00473869680320454"
        iyz="-7.59085432106584E-18"
        izz="0.00237094198835257" />
    </inertial>
    <visual>
      <origin
        xyz="0 0 0"
        rpy="0 0 0" />
      <geometry>
        <mesh
          filename="package://fyp_sim/meshes/front_wheel.stl" scale="0.01 0.01 0.01"/>
      </geometry>
      <material
        name="front_wheel_left_material">
        <color
          rgba="0.0 0.0 0.0 1.0" />
      </material>
    </visual>
    <collision name="front_wheel_left_collision">
      <origin
        xyz="0 0 0"
        rpy="0 0 0" />
      <geometry>
        <mesh
          filename="package://fyp_sim/meshes/front_wheel.stl" scale="0.01 0.01 0.01"/>
      </geometry>
      <surface>
        <friction>
          <ode>
            <mu>0.8</mu>
            <mu2>0.8</mu2>
            <slip1>1.0</slip1>
            <slip2>1.0</slip2>
          </ode>
        </friction>
      </surface>
    </collision>
  </link>


  <joint name="base_joint" type="fixed">
    <origin
      xyz="0 0 0.22987"
      rpy="0 0 ${-pi}" />
    <parent
      link="base_footprint" />
    <child
      link="chassis" />
  </joint>

  <joint name="back_LW_joint"
    type="continuous">
    <origin
      xyz="0.23591 -0.245 -0.06987"
      rpy="${pi/2} 0 0" />
    <parent
      link="chassis" />
    <child
      link="back_wheel_left" />
    <axis
      xyz="0 0 1" />
  </joint>

  <joint name="back_RW_joint"
    type="continuous">
    <origin
      xyz="0.23591 0.245 -0.06987"
      rpy="${-pi/2} 0 0" />
    <parent
      link="chassis" />
    <child
      link="back_wheel_right" />
    <axis
      xyz="0 0 -1" />
  </joint>

  <joint name="front_LW_con_joint"
    type="revolute">
    <limit effort="30" velocity="${pi/3}" lower="${-pi/2}" upper="${pi/2}"/>
    <origin
      xyz="-0.35409 -0.22 0.02013"
      rpy="0 0 ${pi/2}" />
    <parent
      link="chassis" />
    <child
      link="front_wheel_left_connector" />
    <axis
      xyz="0 0 1" />
  </joint>

  <joint name="front_RW_con_joint"
    type="revolute">
    <limit effort="30" velocity="${pi/3}" lower="${-pi/2}" upper="${pi/2}"/>
    <origin
      xyz="-0.35409 0.22 0.02013"
      rpy="0 0 ${pi/2}" />
    <parent
      link="chassis" />
    <child
      link="front_wheel_right_connector" />
    <axis
      xyz="0 0 1" />
  </joint>

  <joint name="front_RW_joint"
    type="continuous">
    <origin
      xyz="0 0 -0.15"
      rpy="0 ${pi/2} 0" />
    <parent
      link="front_wheel_right_connector" />
    <child
      link="front_wheel_right" />
    <axis
      xyz="0 0 1" />
  </joint>

<!-- "-0.35409 -0.22 -0.13487" -->

  <joint name="front_LW_joint"
    type="continuous">
    <origin
      xyz="0 0 -0.15"
      rpy="0 ${-pi/2} 0" />
    <parent
      link="front_wheel_left_connector"/>
    <child
      link="front_wheel_left" />
    <axis
      xyz="0 0 1" />
  </joint>

  <transmission name="back_LW_transmission">
    <type>transmission_interface/SimpleTransmission</type>
    <joint name="back_LW_joint">
      <hardwareInterface>hardware_interface/EffortJointInterface</hardwareInterface>
    </joint>
    <actuator name="back_LW_motor">
      <mechanicalReduction>1</mechanicalReduction>
      <hardwareInterface>EffortJointInterface</hardwareInterface>
    </actuator>
  </transmission>

  <transmission name="back_RW_transmission">
    <type>transmission_interface/SimpleTransmission</type>
    <joint name="back_RW_joint">
      <hardwareInterface>hardware_interface/EffortJointInterface</hardwareInterface>
    </joint>
    <actuator name="back_RW_motor">
      <mechanicalReduction>1</mechanicalReduction>
      <hardwareInterface>EffortJointInterface</hardwareInterface>
    </actuator>
  </transmission>

  <transmission name="front_RW_con_transmission">
    <type>transmission_interface/SimpleTransmission</type>
    <joint name="front_RW_con_joint">
      <hardwareInterface>hardware_interface/EffortJointInterface</hardwareInterface>
    </joint>
    <actuator name="front_RW_con_motor">
      <mechanicalReduction>1</mechanicalReduction>
      <hardwareInterface>EffortJointInterface</hardwareInterface>
    </actuator>
  </transmission>

  <transmission name="front_LW_con_transmission">
    <type>transmission_interface/SimpleTransmission</type>
    <joint name="front_LW_con_joint">
      <hardwareInterface>hardware_interface/EffortJointInterface</hardwareInterface>
    </joint>
    <actuator name="front_LW_con_motor">
      <mechanicalReduction>1</mechanicalReduction>
      <hardwareInterface>EffortJointInterface</hardwareInterface>
    </actuator>
  </transmission>

  <!--For caster wheels; not for physical robot; only for simulation -->

  <transmission name="front_RW_transmission">
    <type>transmission_interface/SimpleTransmission</type>
    <joint name="front_RW_joint">
      <hardwareInterface>hardware_interface/EffortJointInterface</hardwareInterface>
    </joint>
    <actuator name="front_RW_motor">
      <mechanicalReduction>1</mechanicalReduction>
      <hardwareInterface>EffortJointInterface</hardwareInterface>
    </actuator>
  </transmission>

  <transmission name="front_LW_transmission">
    <type>transmission_interface/SimpleTransmission</type>
    <joint name="front_LW_joint">
      <hardwareInterface>hardware_interface/EffortJointInterface</hardwareInterface>
    </joint>
    <actuator name="front_LW_motor">
      <mechanicalReduction>1</mechanicalReduction>
      <hardwareInterface>EffortJointInterface</hardwareInterface>
    </actuator>
  </transmission>

</robot>
